<?xml version="1.0" encoding="UTF-8"?>
<testng-results ignored="0" total="6" passed="3" failed="2" skipped="1">
  <reporter-output>
  </reporter-output>
  <suite started-at="2024-10-28T16:47:14 IST" name="Suite" finished-at="2024-10-28T16:47:22 IST" duration-ms="7491">
    <groups>
    </groups>
    <test started-at="2024-10-28T16:47:14 IST" name="Test" finished-at="2024-10-28T16:47:22 IST" duration-ms="7491">
      <class name="providerTestCases.Debit_2">
        <test-method signature="debitValidTest()[pri:1, instance:providerTestCases.Debit_2@1df8da7a]" started-at="2024-10-28T16:47:21 IST" name="debitValidTest" finished-at="2024-10-28T16:47:22 IST" duration-ms="910" status="FAIL">
          <exception class="java.lang.AssertionError">
            <message>
              <![CDATA[1 expectation failed.
Expected status code <200> but was <502>.
]]>
            </message>
            <full-stacktrace>
              <![CDATA[java.lang.AssertionError: 1 expectation failed.
Expected status code <200> but was <502>.

at java.base/jdk.internal.reflect.DirectConstructorHandleAccessor.newInstance(DirectConstructorHandleAccessor.java:62)
at java.base/java.lang.reflect.Constructor.newInstanceWithCaller(Constructor.java:501)
at java.base/java.lang.reflect.Constructor.newInstance(Constructor.java:485)
at org.codehaus.groovy.reflection.CachedConstructor.invoke(CachedConstructor.java:73)
at org.codehaus.groovy.runtime.callsite.ConstructorSite$ConstructorSiteNoUnwrapNoCoerce.callConstructor(ConstructorSite.java:108)
at org.codehaus.groovy.runtime.callsite.CallSiteArray.defaultCallConstructor(CallSiteArray.java:57)
at org.codehaus.groovy.runtime.callsite.AbstractCallSite.callConstructor(AbstractCallSite.java:263)
at org.codehaus.groovy.runtime.callsite.AbstractCallSite.callConstructor(AbstractCallSite.java:277)
at io.restassured.internal.ResponseSpecificationImpl$HamcrestAssertionClosure.validate(ResponseSpecificationImpl.groovy:512)
at io.restassured.internal.ResponseSpecificationImpl$HamcrestAssertionClosure$validate$1.call(Unknown Source)
at org.codehaus.groovy.runtime.callsite.CallSiteArray.defaultCall(CallSiteArray.java:45)
at org.codehaus.groovy.runtime.callsite.AbstractCallSite.call(AbstractCallSite.java:125)
at org.codehaus.groovy.runtime.callsite.AbstractCallSite.call(AbstractCallSite.java:139)
at io.restassured.internal.ResponseSpecificationImpl.validateResponseIfRequired(ResponseSpecificationImpl.groovy:696)
at io.restassured.internal.ResponseSpecificationImpl.this$2$validateResponseIfRequired(ResponseSpecificationImpl.groovy)
at java.base/jdk.internal.reflect.DirectMethodHandleAccessor.invoke(DirectMethodHandleAccessor.java:103)
at java.base/java.lang.reflect.Method.invoke(Method.java:580)
at org.codehaus.groovy.runtime.callsite.PlainObjectMetaMethodSite.doInvoke(PlainObjectMetaMethodSite.java:43)
at org.codehaus.groovy.runtime.callsite.PogoMetaMethodSite$PogoCachedMethodSiteNoUnwrapNoCoerce.invoke(PogoMetaMethodSite.java:198)
at org.codehaus.groovy.runtime.callsite.PogoMetaMethodSite.callCurrent(PogoMetaMethodSite.java:62)
at org.codehaus.groovy.runtime.callsite.CallSiteArray.defaultCallCurrent(CallSiteArray.java:49)
at org.codehaus.groovy.runtime.callsite.AbstractCallSite.callCurrent(AbstractCallSite.java:171)
at org.codehaus.groovy.runtime.callsite.AbstractCallSite.callCurrent(AbstractCallSite.java:185)
at io.restassured.internal.ResponseSpecificationImpl.statusCode(ResponseSpecificationImpl.groovy:135)
at io.restassured.specification.ResponseSpecification$statusCode$0.callCurrent(Unknown Source)
at org.codehaus.groovy.runtime.callsite.CallSiteArray.defaultCallCurrent(CallSiteArray.java:49)
at org.codehaus.groovy.runtime.callsite.AbstractCallSite.callCurrent(AbstractCallSite.java:171)
at org.codehaus.groovy.runtime.callsite.AbstractCallSite.callCurrent(AbstractCallSite.java:185)
at io.restassured.internal.ResponseSpecificationImpl.statusCode(ResponseSpecificationImpl.groovy:143)
at io.restassured.internal.ValidatableResponseOptionsImpl.statusCode(ValidatableResponseOptionsImpl.java:89)
at providerTestCases.Debit_2.debitValidTest(Debit_2.java:33)
at java.base/jdk.internal.reflect.DirectMethodHandleAccessor.invoke(DirectMethodHandleAccessor.java:103)
at java.base/java.lang.reflect.Method.invoke(Method.java:580)
at org.testng.internal.invokers.MethodInvocationHelper.invokeMethod(MethodInvocationHelper.java:141)
at org.testng.internal.invokers.TestInvoker.invokeMethod(TestInvoker.java:686)
at org.testng.internal.invokers.TestInvoker.invokeTestMethod(TestInvoker.java:230)
at org.testng.internal.invokers.MethodRunner.runInSequence(MethodRunner.java:63)
at org.testng.internal.invokers.TestInvoker$MethodInvocationAgent.invoke(TestInvoker.java:992)
at org.testng.internal.invokers.TestInvoker.invokeTestMethods(TestInvoker.java:203)
at org.testng.internal.invokers.TestMethodWorker.invokeTestMethods(TestMethodWorker.java:154)
at org.testng.internal.invokers.TestMethodWorker.run(TestMethodWorker.java:134)
at java.base/java.util.ArrayList.forEach(ArrayList.java:1597)
at org.testng.TestRunner.privateRun(TestRunner.java:739)
at org.testng.TestRunner.run(TestRunner.java:614)
at org.testng.SuiteRunner.runTest(SuiteRunner.java:421)
at org.testng.SuiteRunner.runSequentially(SuiteRunner.java:413)
at org.testng.SuiteRunner.privateRun(SuiteRunner.java:373)
at org.testng.SuiteRunner.run(SuiteRunner.java:312)
at org.testng.SuiteRunnerWorker.runSuite(SuiteRunnerWorker.java:52)
at org.testng.SuiteRunnerWorker.run(SuiteRunnerWorker.java:95)
at org.testng.TestNG.runSuitesSequentially(TestNG.java:1274)
at org.testng.TestNG.runSuitesLocally(TestNG.java:1208)
at org.testng.TestNG.runSuites(TestNG.java:1112)
at org.testng.TestNG.run(TestNG.java:1079)
at org.testng.remote.AbstractRemoteTestNG.run(AbstractRemoteTestNG.java:115)
at org.testng.remote.RemoteTestNG.initAndRun(RemoteTestNG.java:293)
at org.testng.remote.RemoteTestNG.main(RemoteTestNG.java:91)
]]>
            </full-stacktrace>
          </exception> <!-- java.lang.AssertionError -->
          <reporter-output>
          </reporter-output>
        </test-method> <!-- debitValidTest -->
      </class> <!-- providerTestCases.Debit_2 -->
      <class name="providerTestCases.Repeated_Authentication_1">
        <test-method is-config="true" signature="variables()[pri:0, instance:providerTestCases.Repeated_Authentication_1@38145825]" started-at="2024-10-28T16:47:13 IST" name="variables" finished-at="2024-10-28T16:47:14 IST" duration-ms="775" status="PASS">
          <reporter-output>
          </reporter-output>
        </test-method> <!-- variables -->
        <test-method is-config="true" signature="testVariables()[pri:0, instance:providerTestCases.Repeated_Authentication_1@38145825]" started-at="2024-10-28T16:47:14 IST" name="testVariables" finished-at="2024-10-28T16:47:14 IST" duration-ms="29" status="PASS">
          <reporter-output>
          </reporter-output>
        </test-method> <!-- testVariables -->
        <test-method signature="getURLValidTest()[pri:0, instance:providerTestCases.Repeated_Authentication_1@38145825]" started-at="2024-10-28T16:47:14 IST" name="getURLValidTest" finished-at="2024-10-28T16:47:18 IST" duration-ms="3493" status="PASS">
          <reporter-output>
          </reporter-output>
        </test-method> <!-- getURLValidTest -->
        <test-method signature="authenticationValidTest()[pri:0, instance:providerTestCases.Repeated_Authentication_1@38145825]" started-at="2024-10-28T16:47:18 IST" name="authenticationValidTest" finished-at="2024-10-28T16:47:19 IST" depends-on-methods="providerTestCases.Repeated_Authentication_1.getURLValidTest" duration-ms="1024" status="PASS">
          <reporter-output>
          </reporter-output>
        </test-method> <!-- authenticationValidTest -->
        <test-method signature="authenticationValidTest()[pri:0, instance:providerTestCases.Repeated_Authentication_1@38145825]" started-at="2024-10-28T16:47:19 IST" name="authenticationValidTest" finished-at="2024-10-28T16:47:20 IST" depends-on-methods="providerTestCases.Repeated_Authentication_1.getURLValidTest" duration-ms="765" status="PASS">
          <reporter-output>
          </reporter-output>
        </test-method> <!-- authenticationValidTest -->
      </class> <!-- providerTestCases.Repeated_Authentication_1 -->
      <class name="providerTestCases.Authentication_0">
        <test-method signature="getURLValidTest()[pri:0, instance:providerTestCases.Authentication_0@37313c65]" started-at="2024-10-28T16:47:20 IST" name="getURLValidTest" finished-at="2024-10-28T16:47:21 IST" duration-ms="1175" status="FAIL">
          <exception class="io.restassured.path.json.exception.JsonPathException">
            <message>
              <![CDATA[Failed to parse the JSON document]]>
            </message>
            <full-stacktrace>
              <![CDATA[io.restassured.path.json.exception.JsonPathException: Failed to parse the JSON document
at io.restassured.path.json.JsonPath$ExceptionCatcher.invoke(JsonPath.java:1002)
at io.restassured.path.json.JsonPath$4.doParseWith(JsonPath.java:967)
at io.restassured.path.json.JsonPath$JsonParser.parseWith(JsonPath.java:1047)
at io.restassured.path.json.JsonPath.get(JsonPath.java:202)
at api_genericutility.JsonUtility.getValueJsonFromBody(JsonUtility.java:8)
at providerTestCases.Authentication_0.getURLValidTest(Authentication_0.java:30)
at java.base/jdk.internal.reflect.DirectMethodHandleAccessor.invoke(DirectMethodHandleAccessor.java:103)
at java.base/java.lang.reflect.Method.invoke(Method.java:580)
at org.testng.internal.invokers.MethodInvocationHelper.invokeMethod(MethodInvocationHelper.java:141)
at org.testng.internal.invokers.TestInvoker.invokeMethod(TestInvoker.java:686)
at org.testng.internal.invokers.TestInvoker.invokeTestMethod(TestInvoker.java:230)
at org.testng.internal.invokers.MethodRunner.runInSequence(MethodRunner.java:63)
at org.testng.internal.invokers.TestInvoker$MethodInvocationAgent.invoke(TestInvoker.java:992)
at org.testng.internal.invokers.TestInvoker.invokeTestMethods(TestInvoker.java:203)
at org.testng.internal.invokers.TestMethodWorker.invokeTestMethods(TestMethodWorker.java:154)
at org.testng.internal.invokers.TestMethodWorker.run(TestMethodWorker.java:134)
at java.base/java.util.ArrayList.forEach(ArrayList.java:1597)
at org.testng.TestRunner.privateRun(TestRunner.java:739)
at org.testng.TestRunner.run(TestRunner.java:614)
at org.testng.SuiteRunner.runTest(SuiteRunner.java:421)
at org.testng.SuiteRunner.runSequentially(SuiteRunner.java:413)
at org.testng.SuiteRunner.privateRun(SuiteRunner.java:373)
at org.testng.SuiteRunner.run(SuiteRunner.java:312)
at org.testng.SuiteRunnerWorker.runSuite(SuiteRunnerWorker.java:52)
at org.testng.SuiteRunnerWorker.run(SuiteRunnerWorker.java:95)
at org.testng.TestNG.runSuitesSequentially(TestNG.java:1274)
at org.testng.TestNG.runSuitesLocally(TestNG.java:1208)
at org.testng.TestNG.runSuites(TestNG.java:1112)
at org.testng.TestNG.run(TestNG.java:1079)
at org.testng.remote.AbstractRemoteTestNG.run(AbstractRemoteTestNG.java:115)
at org.testng.remote.RemoteTestNG.initAndRun(RemoteTestNG.java:293)
at org.testng.remote.RemoteTestNG.main(RemoteTestNG.java:91)
Caused by: groovy.json.JsonException: Lexing failed on line: 1, column: 1, while reading '<', no possible valid JSON value or punctuation could be recognized.
at groovy.json.JsonLexer.nextToken(JsonLexer.java:86)
at groovy.json.JsonLexer$nextToken.call(Unknown Source)
at io.restassured.internal.path.json.ConfigurableJsonSlurper.parse(ConfigurableJsonSlurper.groovy:97)
at io.restassured.internal.path.json.ConfigurableJsonSlurper$parse.callCurrent(Unknown Source)
at io.restassured.internal.path.json.ConfigurableJsonSlurper.parseText(ConfigurableJsonSlurper.groovy:83)
at io.restassured.path.json.JsonPath$4$1.method(JsonPath.java:965)
at io.restassured.path.json.JsonPath$ExceptionCatcher.invoke(JsonPath.java:1000)
... 31 more
]]>
            </full-stacktrace>
          </exception> <!-- io.restassured.path.json.exception.JsonPathException -->
          <reporter-output>
          </reporter-output>
        </test-method> <!-- getURLValidTest -->
        <test-method signature="authenticationValidTest()[pri:0, instance:providerTestCases.Authentication_0@37313c65]" started-at="2024-10-28T16:47:21 IST" name="authenticationValidTest" finished-at="2024-10-28T16:47:21 IST" depends-on-methods="providerTestCases.Authentication_0.getURLValidTest" duration-ms="0" status="SKIP">
          <exception class="java.lang.Throwable">
            <message>
              <![CDATA[Method providerTestCases.Authentication_0.authenticationValidTest() on instance providerTestCases.Authentication_0@37313c65 depends on not successfully finished methods 
[providerTestCases.Authentication_0.getURLValidTest() on instance providerTestCases.Authentication_0@37313c65]]]>
            </message>
            <full-stacktrace>
              <![CDATA[java.lang.Throwable: Method providerTestCases.Authentication_0.authenticationValidTest() on instance providerTestCases.Authentication_0@37313c65 depends on not successfully finished methods 
[providerTestCases.Authentication_0.getURLValidTest() on instance providerTestCases.Authentication_0@37313c65]
at org.testng.internal.invokers.TestInvoker.invokeTestMethods(TestInvoker.java:159)
at org.testng.internal.invokers.TestMethodWorker.invokeTestMethods(TestMethodWorker.java:154)
at org.testng.internal.invokers.TestMethodWorker.run(TestMethodWorker.java:134)
at java.base/java.util.ArrayList.forEach(ArrayList.java:1597)
at org.testng.TestRunner.privateRun(TestRunner.java:739)
at org.testng.TestRunner.run(TestRunner.java:614)
at org.testng.SuiteRunner.runTest(SuiteRunner.java:421)
at org.testng.SuiteRunner.runSequentially(SuiteRunner.java:413)
at org.testng.SuiteRunner.privateRun(SuiteRunner.java:373)
at org.testng.SuiteRunner.run(SuiteRunner.java:312)
at org.testng.SuiteRunnerWorker.runSuite(SuiteRunnerWorker.java:52)
at org.testng.SuiteRunnerWorker.run(SuiteRunnerWorker.java:95)
at org.testng.TestNG.runSuitesSequentially(TestNG.java:1274)
at org.testng.TestNG.runSuitesLocally(TestNG.java:1208)
at org.testng.TestNG.runSuites(TestNG.java:1112)
at org.testng.TestNG.run(TestNG.java:1079)
at org.testng.remote.AbstractRemoteTestNG.run(AbstractRemoteTestNG.java:115)
at org.testng.remote.RemoteTestNG.initAndRun(RemoteTestNG.java:293)
at org.testng.remote.RemoteTestNG.main(RemoteTestNG.java:91)
]]>
            </full-stacktrace>
          </exception> <!-- java.lang.Throwable -->
          <reporter-output>
          </reporter-output>
        </test-method> <!-- authenticationValidTest -->
      </class> <!-- providerTestCases.Authentication_0 -->
    </test> <!-- Test -->
  </suite> <!-- Suite -->
</testng-results>
